Workbook

Sheet P&L Dashboard
A1: VELOCITYMATCH - P&L DASHBOARD
A2: 24-Month Financial Performance
A5: Month | B5: Total Revenue | C5: Matching Engine | D5: Placements | E5: Add-ons | F5: COGS | G5: Gross Profit | H5: OpEx | I5: Net Profit | J5: Gross Margin % | K5: Net Margin %
A6: M1 | B6: ='P&L'!C33 -> 25252 | C6: ='P&L'!C29 -> 1196 | D6: ='P&L'!C30 -> 24000 | E6: ='P&L'!C31 -> 0 | F6: ='P&L'!C37 -> 1360 | G6: ='P&L'!C38 -> 23892 | H6: ='P&L'!C40 -> 18989.5 | I6: ='P&L'!C41 -> 4902.5 | J6: ='P&L'!C39 -> 0.94614288 | K6: ='P&L'!C42 -> 0.19414304
A7: M2 | B7: ='P&L'!D33 -> 31565 | C7: ='P&L'!D29 -> 1495 | D7: ='P&L'!D30 -> 30000 | E7: ='P&L'!D31 -> 0 | F7: ='P&L'!D37 -> 1700 | G7: ='P&L'!D38 -> 29865 | H7: ='P&L'!D40 -> 18989.5 | I7: ='P&L'!D41 -> 10875.5 | J7: ='P&L'!D39 -> 0.94614288 | K7: ='P&L'!D42 -> 0.34454301
A8: M3 | B8: ='P&L'!E33 -> 37878 | C8: ='P&L'!E29 -> 1794 | D8: ='P&L'!E30 -> 36000 | E8: ='P&L'!E31 -> 0 | F8: ='P&L'!E37 -> 2040 | G8: ='P&L'!E38 -> 35838 | H8: ='P&L'!E40 -> 23793.667 | I8: ='P&L'!E41 -> 12044.333 | J8: ='P&L'!E39 -> 0.94614288 | K8: ='P&L'!E42 -> 0.31797701
A9: M4 | B9: ='P&L'!F33 -> 45871 | C9: ='P&L'!F29 -> 2093 | D9: ='P&L'!F30 -> 42000 | E9: ='P&L'!F31 -> 1680 | F9: ='P&L'!F37 -> 2548 | G9: ='P&L'!F38 -> 43323 | H9: ='P&L'!F40 -> 23793.667 | I9: ='P&L'!F41 -> 19529.333 | J9: ='P&L'!F39 -> 0.94445292 | K9: ='P&L'!F42 -> 0.42574466
A10: M5 | B10: ='P&L'!G33 -> 52424 | C10: ='P&L'!G29 -> 2392 | D10: ='P&L'!G30 -> 48000 | E10: ='P&L'!G31 -> 1920 | F10: ='P&L'!G37 -> 2912 | G10: ='P&L'!G38 -> 49512 | H10: ='P&L'!G40 -> 23793.667 | I10: ='P&L'!G41 -> 25718.333 | J10: ='P&L'!G39 -> 0.94445292 | K10: ='P&L'!G42 -> 0.49058319
A11: M6 | B11: ='P&L'!H33 -> 58977 | C11: ='P&L'!H29 -> 2691 | D11: ='P&L'!H30 -> 54000 | E11: ='P&L'!H31 -> 2160 | F11: ='P&L'!H37 -> 3276 | G11: ='P&L'!H38 -> 55701 | H11: ='P&L'!H40 -> 23793.667 | I11: ='P&L'!H41 -> 31907.333 | J11: ='P&L'!H39 -> 0.94445292 | K11: ='P&L'!H42 -> 0.54101316
A12: M7 | B12: ='P&L'!I33 -> 65530 | C12: ='P&L'!I29 -> 2990 | D12: ='P&L'!I30 -> 60000 | E12: ='P&L'!I31 -> 2400 | F12: ='P&L'!I37 -> 3640 | G12: ='P&L'!I38 -> 61890 | H12: ='P&L'!I40 -> 25177.267 | I12: ='P&L'!I41 -> 36712.733 | J12: ='P&L'!I39 -> 0.94445292 | K12: ='P&L'!I42 -> 0.56024315
A13: M8 | B13: ='P&L'!J33 -> 72083 | C13: ='P&L'!J29 -> 3289 | D13: ='P&L'!J30 -> 66000 | E13: ='P&L'!J31 -> 2640 | F13: ='P&L'!J37 -> 4004 | G13: ='P&L'!J38 -> 68079 | H13: ='P&L'!J40 -> 25177.267 | I13: ='P&L'!J41 -> 42901.733 | J13: ='P&L'!J39 -> 0.94445292 | K13: ='P&L'!J42 -> 0.59517131
A14: M9 | B14: ='P&L'!K33 -> 78636 | C14: ='P&L'!K29 -> 3588 | D14: ='P&L'!K30 -> 72000 | E14: ='P&L'!K31 -> 2880 | F14: ='P&L'!K37 -> 4368 | G14: ='P&L'!K38 -> 74268 | H14: ='P&L'!K40 -> 25177.267 | I14: ='P&L'!K41 -> 49090.733 | J14: ='P&L'!K39 -> 0.94445292 | K14: ='P&L'!K42 -> 0.62427811
A15: M10 | B15: ='P&L'!L33 -> 85189 | C15: ='P&L'!L29 -> 3887 | D15: ='P&L'!L30 -> 78000 | E15: ='P&L'!L31 -> 3120 | F15: ='P&L'!L37 -> 4732 | G15: ='P&L'!L38 -> 80457 | H15: ='P&L'!L40 -> 25177.267 | I15: ='P&L'!L41 -> 55279.733 | J15: ='P&L'!L39 -> 0.94445292 | K15: ='P&L'!L42 -> 0.64890694
A16: M11 | B16: ='P&L'!M33 -> 91742 | C16: ='P&L'!M29 -> 4186 | D16: ='P&L'!M30 -> 84000 | E16: ='P&L'!M31 -> 3360 | F16: ='P&L'!M37 -> 5096 | G16: ='P&L'!M38 -> 86646 | H16: ='P&L'!M40 -> 25177.267 | I16: ='P&L'!M41 -> 61468.733 | J16: ='P&L'!M39 -> 0.94445292 | K16: ='P&L'!M42 -> 0.67001737
A17: M12 | B17: ='P&L'!N33 -> 98295 | C17: ='P&L'!N29 -> 4485 | D17: ='P&L'!N30 -> 90000 | E17: ='P&L'!N31 -> 3600 | F17: ='P&L'!N37 -> 5460 | G17: ='P&L'!N38 -> 92835 | H17: ='P&L'!N40 -> 25177.267 | I17: ='P&L'!N41 -> 67657.733 | J17: ='P&L'!N39 -> 0.94445292 | K17: ='P&L'!N42 -> 0.68831307
A18: M13 | B18: ='P&L'!O33 -> 124507 | C18: ='P&L'!O29 -> 5681 | D18: ='P&L'!O30 -> 114000 | E18: ='P&L'!O31 -> 4560 | F18: ='P&L'!O37 -> 6916 | G18: ='P&L'!O38 -> 117591 | H18: ='P&L'!O40 -> 27694.993 | I18: ='P&L'!O41 -> 89896.007 | J18: ='P&L'!O39 -> 0.94445292 | K18: ='P&L'!O42 -> 0.72201568
A19: M14 | B19: ='P&L'!P33 -> 157272 | C19: ='P&L'!P29 -> 7176 | D19: ='P&L'!P30 -> 144000 | E19: ='P&L'!P31 -> 5760 | F19: ='P&L'!P37 -> 8736 | G19: ='P&L'!P38 -> 148536 | H19: ='P&L'!P40 -> 27694.993 | I19: ='P&L'!P41 -> 120841.01 | J19: ='P&L'!P39 -> 0.94445292 | K19: ='P&L'!P42 -> 0.76835677
A20: M15 | B20: ='P&L'!Q33 -> 196590 | C20: ='P&L'!Q29 -> 8970 | D20: ='P&L'!Q30 -> 180000 | E20: ='P&L'!Q31 -> 7200 | F20: ='P&L'!Q37 -> 10920 | G20: ='P&L'!Q38 -> 185670 | H20: ='P&L'!Q40 -> 27694.993 | I20: ='P&L'!Q41 -> 157975.01 | J20: ='P&L'!Q39 -> 0.94445292 | K20: ='P&L'!Q42 -> 0.803576
A21: M16 | B21: ='P&L'!R33 -> 249014 | C21: ='P&L'!R29 -> 11362 | D21: ='P&L'!R30 -> 228000 | E21: ='P&L'!R31 -> 9120 | F21: ='P&L'!R37 -> 13832 | G21: ='P&L'!R38 -> 235182 | H21: ='P&L'!R40 -> 27694.993 | I21: ='P&L'!R41 -> 207487.01 | J21: ='P&L'!R39 -> 0.94445292 | K21: ='P&L'!R42 -> 0.8332343
A22: M17 | B22: ='P&L'!S33 -> 307991 | C22: ='P&L'!S29 -> 14053 | D22: ='P&L'!S30 -> 282000 | E22: ='P&L'!S31 -> 11280 | F22: ='P&L'!S37 -> 17108 | G22: ='P&L'!S38 -> 290883 | H22: ='P&L'!S40 -> 27694.993 | I22: ='P&L'!S41 -> 263188.01 | J22: ='P&L'!S39 -> 0.94445292 | K22: ='P&L'!S42 -> 0.85453149
A23: M18 | B23: ='P&L'!T33 -> 386627 | C23: ='P&L'!T29 -> 17641 | D23: ='P&L'!T30 -> 354000 | E23: ='P&L'!T31 -> 14160 | F23: ='P&L'!T37 -> 21476 | G23: ='P&L'!T38 -> 365151 | H23: ='P&L'!T40 -> 27694.993 | I23: ='P&L'!T41 -> 337456.01 | J23: ='P&L'!T39 -> 0.94445292 | K23: ='P&L'!T42 -> 0.87282059
A24: M19 | B24: ='P&L'!U33 -> 491475 | C24: ='P&L'!U29 -> 22425 | D24: ='P&L'!U30 -> 450000 | E24: ='P&L'!U31 -> 18000 | F24: ='P&L'!U37 -> 27300 | G24: ='P&L'!U38 -> 464175 | H24: ='P&L'!U40 -> 27694.993 | I24: ='P&L'!U41 -> 436480.01 | J24: ='P&L'!U39 -> 0.94445292 | K24: ='P&L'!U42 -> 0.88810216
A25: M20 | B25: ='P&L'!V33 -> 622535 | C25: ='P&L'!V29 -> 28405 | D25: ='P&L'!V30 -> 570000 | E25: ='P&L'!V31 -> 22800 | F25: ='P&L'!V37 -> 34580 | G25: ='P&L'!V38 -> 587955 | H25: ='P&L'!V40 -> 27694.993 | I25: ='P&L'!V41 -> 560260.01 | J25: ='P&L'!V39 -> 0.94445292 | K25: ='P&L'!V42 -> 0.89996547
A26: M21 | B26: ='P&L'!W33 -> 786360 | C26: ='P&L'!W29 -> 35880 | D26: ='P&L'!W30 -> 720000 | E26: ='P&L'!W31 -> 28800 | F26: ='P&L'!W37 -> 43680 | G26: ='P&L'!W38 -> 742680 | H26: ='P&L'!W40 -> 27694.993 | I26: ='P&L'!W41 -> 714985.01 | J26: ='P&L'!W39 -> 0.94445292 | K26: ='P&L'!W42 -> 0.90923369
A27: M22 | B27: ='P&L'!X33 -> 989503 | C27: ='P&L'!X29 -> 45149 | D27: ='P&L'!X30 -> 906000 | E27: ='P&L'!X31 -> 36240 | F27: ='P&L'!X37 -> 54964 | G27: ='P&L'!X38 -> 934539 | H27: ='P&L'!X40 -> 27694.993 | I27: ='P&L'!X41 -> 906844.01 | J27: ='P&L'!X39 -> 0.94445292 | K27: ='P&L'!X42 -> 0.91646413
A28: M23 | B28: ='P&L'!Y33 -> 1245070 | C28: ='P&L'!Y29 -> 56810 | D28: ='P&L'!Y30 -> 1140000 | E28: ='P&L'!Y31 -> 45600 | F28: ='P&L'!Y37 -> 69160 | G28: ='P&L'!Y38 -> 1175910 | H28: ='P&L'!Y40 -> 27694.993 | I28: ='P&L'!Y41 -> 1148215 | J28: ='P&L'!Y39 -> 0.94445292 | K28: ='P&L'!Y42 -> 0.9222092
A29: M24 | B29: ='P&L'!Z33 -> 1566167 | C29: ='P&L'!Z29 -> 71461 | D29: ='P&L'!Z30 -> 1434000 | E29: ='P&L'!Z31 -> 57360 | F29: ='P&L'!Z37 -> 86996 | G29: ='P&L'!Z38 -> 1479171 | H29: ='P&L'!Z40 -> 27694.993 | I29: ='P&L'!Z41 -> 1451476 | J29: ='P&L'!Z39 -> 0.94445292 | K29: ='P&L'!Z42 -> 0.92676963
A31: Data validation: Dashboard linked to P&L with churn-adjusted carriers

Sheet Cash Flow Dashboard
A1: VELOCITYMATCH - CASH FLOW DASHBOARD
A2: Cash Position & Runway Analysis
A5: Month | B5: Beginning Cash | C5: Cash Inflows | D5: Cash Outflows | E5: Net Cash Flow | F5: Ending Cash | G5: Runway (Months)
A6: M1 | B6: ='Cash Flow'!C15 -> 187974 | C6: ='Cash Flow'!C18 -> 0 | D6: ='Cash Flow'!C22 -> 95349.5 | E6: ='Cash Flow'!C23 -> -95349.5 | F6: ='Cash Flow'!C24 -> 92624.5 | G6: ='Cash Flow'!C26 -> 4.8776692
A7: M2 | B7: ='Cash Flow'!D15 -> 92624.5 | C7: ='Cash Flow'!D18 -> 23989.4 | D7: ='Cash Flow'!D22 -> 20689.5 | E7: ='Cash Flow'!D23 -> 3299.9 | F7: ='Cash Flow'!D24 -> 95924.4 | G7: ='Cash Flow'!D26 -> 5.0514442
A8: M3 | B8: ='Cash Flow'!E15 -> 95924.4 | C8: ='Cash Flow'!E18 -> 29986.75 | D8: ='Cash Flow'!E22 -> 25833.667 | E8: ='Cash Flow'!E23 -> 4153.0833 | F8: ='Cash Flow'!E24 -> 100077.48 | G8: ='Cash Flow'!E26 -> 4.2060555
A9: M4 | B9: ='Cash Flow'!F15 -> 100077.48 | C9: ='Cash Flow'!F18 -> 35984.1 | D9: ='Cash Flow'!F22 -> 26341.667 | E9: ='Cash Flow'!F23 -> 9642.4333 | F9: ='Cash Flow'!F24 -> 109719.92 | G9: ='Cash Flow'!F26 -> 4.5174021
A10: M5 | B10: ='Cash Flow'!G15 -> 109719.92 | C10: ='Cash Flow'!G18 -> 43577.45 | D10: ='Cash Flow'!G22 -> 26705.667 | E10: ='Cash Flow'!G23 -> 16871.783 | F10: ='Cash Flow'!G24 -> 126591.7 | G10: ='Cash Flow'!G26 -> 4.814532
A11: M6 | B11: ='Cash Flow'!H15 -> 126591.7 | C11: ='Cash Flow'!H18 -> 49802.8 | D11: ='Cash Flow'!H22 -> 27069.667 | E11: ='Cash Flow'!H23 -> 22733.133 | F11: ='Cash Flow'!H24 -> 149324.83 | G11: ='Cash Flow'!H26 -> 5.5915037
A12: M7 | B12: ='Cash Flow'!I15 -> 149324.83 | C12: ='Cash Flow'!I18 -> 56028.15 | D12: ='Cash Flow'!I22 -> 28817.267 | E12: ='Cash Flow'!I23 -> 27210.883 | F12: ='Cash Flow'!I24 -> 176535.72 | G12: ='Cash Flow'!I26 -> 6.4122833
A13: M8 | B13: ='Cash Flow'!J15 -> 176535.72 | C13: ='Cash Flow'!J18 -> 62253.5 | D13: ='Cash Flow'!J22 -> 29181.267 | E13: ='Cash Flow'!J23 -> 33072.233 | F13: ='Cash Flow'!J24 -> 209607.95 | G13: ='Cash Flow'!J26 -> 7.3919967
A14: M9 | B14: ='Cash Flow'!K15 -> 209607.95 | C14: ='Cash Flow'!K18 -> 68478.85 | D14: ='Cash Flow'!K22 -> 29545.267 | E14: ='Cash Flow'!K23 -> 38933.583 | F14: ='Cash Flow'!K24 -> 248541.53 | G14: ='Cash Flow'!K26 -> 8.5171606
A15: M10 | B15: ='Cash Flow'!L15 -> 248541.53 | C15: ='Cash Flow'!L18 -> 74704.2 | D15: ='Cash Flow'!L22 -> 29909.267 | E15: ='Cash Flow'!L23 -> 44794.933 | F15: ='Cash Flow'!L24 -> 293336.47 | G15: ='Cash Flow'!L26 -> 9.9283743
A16: M11 | B16: ='Cash Flow'!M15 -> 293336.47 | C16: ='Cash Flow'!M18 -> 80929.55 | D16: ='Cash Flow'!M22 -> 30273.267 | E16: ='Cash Flow'!M23 -> 50656.283 | F16: ='Cash Flow'!M24 -> 343992.75 | G16: ='Cash Flow'!M26 -> 11.50121
A17: M12 | B17: ='Cash Flow'!N15 -> 343992.75 | C17: ='Cash Flow'!N18 -> 87154.9 | D17: ='Cash Flow'!N22 -> 30637.267 | E17: ='Cash Flow'!N23 -> 56517.633 | F17: ='Cash Flow'!N24 -> 400510.38 | G17: ='Cash Flow'!N26 -> 13.229837
A18: M13 | B18: ='Cash Flow'!O15 -> 400510.38 | C18: ='Cash Flow'!O18 -> 93380.25 | D18: ='Cash Flow'!O22 -> 34610.993 | E18: ='Cash Flow'!O23 -> 58769.257 | F18: ='Cash Flow'!O24 -> 459279.64 | G18: ='Cash Flow'!O26 -> 14.424381
A19: M14 | B19: ='Cash Flow'!P15 -> 459279.64 | C19: ='Cash Flow'!P18 -> 118281.65 | D19: ='Cash Flow'!P22 -> 36430.993 | E19: ='Cash Flow'!P23 -> 81850.657 | F19: ='Cash Flow'!P24 -> 541130.3 | G19: ='Cash Flow'!P26 -> 15.965803
A20: M15 | B20: ='Cash Flow'!Q15 -> 541130.3 | C20: ='Cash Flow'!Q18 -> 149408.4 | D20: ='Cash Flow'!Q22 -> 38614.993 | E20: ='Cash Flow'!Q23 -> 110793.41 | F20: ='Cash Flow'!Q24 -> 651923.7 | G20: ='Cash Flow'!Q26 -> 17.835354
A21: M16 | B21: ='Cash Flow'!R15 -> 651923.7 | C21: ='Cash Flow'!R18 -> 186760.5 | D21: ='Cash Flow'!R22 -> 41526.993 | E21: ='Cash Flow'!R23 -> 145233.51 | F21: ='Cash Flow'!R24 -> 797157.21 | G21: ='Cash Flow'!R26 -> 20.514802
A22: M17 | B22: ='Cash Flow'!S15 -> 797157.21 | C22: ='Cash Flow'!S18 -> 236563.3 | D22: ='Cash Flow'!S22 -> 44802.993 | E22: ='Cash Flow'!S23 -> 191760.31 | F22: ='Cash Flow'!S24 -> 988917.52 | G22: ='Cash Flow'!S26 -> 23.744472
A23: M18 | B23: ='Cash Flow'!T15 -> 988917.52 | C23: ='Cash Flow'!T18 -> 292591.45 | D23: ='Cash Flow'!T22 -> 49170.993 | E23: ='Cash Flow'!T23 -> 243420.46 | F23: ='Cash Flow'!T24 -> 1232338 | G23: ='Cash Flow'!T26 -> 27.284038
A24: M19 | B24: ='Cash Flow'!U15 -> 1232338 | C24: ='Cash Flow'!U18 -> 367295.65 | D24: ='Cash Flow'!U22 -> 54994.993 | E24: ='Cash Flow'!U23 -> 312300.66 | F24: ='Cash Flow'!U24 -> 1544638.6 | G24: ='Cash Flow'!U26 -> 31.106583
A25: M20 | B25: ='Cash Flow'!V15 -> 1544638.6 | C25: ='Cash Flow'!V18 -> 466901.25 | D25: ='Cash Flow'!V22 -> 62274.993 | E25: ='Cash Flow'!V23 -> 404626.26 | F25: ='Cash Flow'!V24 -> 1949264.9 | G25: ='Cash Flow'!V26 -> 35.134344
A26: M21 | B26: ='Cash Flow'!W15 -> 1949264.9 | C26: ='Cash Flow'!W18 -> 591408.25 | D26: ='Cash Flow'!W22 -> 71374.993 | E26: ='Cash Flow'!W23 -> 520033.26 | F26: ='Cash Flow'!W24 -> 2469298.1 | G26: ='Cash Flow'!W26 -> 39.268972
A27: M22 | B27: ='Cash Flow'!X15 -> 2469298.1 | C27: ='Cash Flow'!X18 -> 747042 | D27: ='Cash Flow'!X22 -> 82658.993 | E27: ='Cash Flow'!X23 -> 664383.01 | F27: ='Cash Flow'!X24 -> 3133681.1 | G27: ='Cash Flow'!X26 -> 43.46118
A28: M23 | B28: ='Cash Flow'!Y15 -> 3133681.1 | C28: ='Cash Flow'!Y18 -> 940027.85 | D28: ='Cash Flow'!Y22 -> 96854.993 | E28: ='Cash Flow'!Y23 -> 843172.86 | F28: ='Cash Flow'!Y24 -> 3976854 | G28: ='Cash Flow'!Y26 -> 47.553153
A29: M24 | B29: ='Cash Flow'!Z15 -> 3976854 | C29: ='Cash Flow'!Z18 -> 1182816.5 | D29: ='Cash Flow'!Z22 -> 114690.99 | E29: ='Cash Flow'!Z23 -> 1068125.5 | F29: ='Cash Flow'!Z24 -> 5044979.5 | G29: ='Cash Flow'!Z26 -> 51.443516
A31: Data validation: Dashboard linked to Cash Flow projections

Sheet Growth Metrics
A1: VELOCITYMATCH - GROWTH METRICS DASHBOARD
A2: Customer Acquisition & Revenue Performance
A5: Month | B5: Active Carriers | C5: New Carriers | D5: Total Revenue | E5: Revenue/Carrier | F5: Placements | G5: Placements/Carrier
A6: M1 | B6: ='Churn Model'!E29 -> 4 | C6: ='P&L'!C28 -> 4 | D6: ='P&L'!C33 -> 25252 | E6: =IFERROR(IF(B6=0,0,D6/B6), 0) -> 6313 | F6: =IFERROR('P&L'!C30/1200, 0) -> 20 | G6: =IFERROR(IF(B6=0,0,F6/B6), 0) -> 5
A7: M2 | B7: ='Churn Model'!E30 -> 5 | C7: ='P&L'!D28-'P&L'!C28 -> 1 | D7: ='P&L'!D33 -> 31565 | E7: =IFERROR(IF(B7=0,0,D7/B7), 0) -> 6313 | F7: =IFERROR('P&L'!D30/1200, 0) -> 25 | G7: =IFERROR(IF(B7=0,0,F7/B7), 0) -> 5
A8: M3 | B8: ='Churn Model'!E31 -> 6 | C8: ='P&L'!E28-'P&L'!D28 -> 1 | D8: ='P&L'!E33 -> 37878 | E8: =IFERROR(IF(B8=0,0,D8/B8), 0) -> 6313 | F8: =IFERROR('P&L'!E30/1200, 0) -> 30 | G8: =IFERROR(IF(B8=0,0,F8/B8), 0) -> 5
A9: M4 | B9: ='Churn Model'!E32 -> 7 | C9: ='P&L'!F28-'P&L'!E28 -> 1 | D9: ='P&L'!F33 -> 45871 | E9: =IFERROR(IF(B9=0,0,D9/B9), 0) -> 6553 | F9: =IFERROR('P&L'!F30/1200, 0) -> 35 | G9: =IFERROR(IF(B9=0,0,F9/B9), 0) -> 5
A10: M5 | B10: ='Churn Model'!E33 -> 8 | C10: ='P&L'!G28-'P&L'!F28 -> 1 | D10: ='P&L'!G33 -> 52424 | E10: =IFERROR(IF(B10=0,0,D10/B10), 0) -> 6553 | F10: =IFERROR('P&L'!G30/1200, 0) -> 40 | G10: =IFERROR(IF(B10=0,0,F10/B10), 0) -> 5
A11: M6 | B11: ='Churn Model'!E34 -> 9 | C11: ='P&L'!H28-'P&L'!G28 -> 1 | D11: ='P&L'!H33 -> 58977 | E11: =IFERROR(IF(B11=0,0,D11/B11), 0) -> 6553 | F11: =IFERROR('P&L'!H30/1200, 0) -> 45 | G11: =IFERROR(IF(B11=0,0,F11/B11), 0) -> 5
A12: M7 | B12: ='Churn Model'!E35 -> 10 | C12: ='P&L'!I28-'P&L'!H28 -> 1 | D12: ='P&L'!I33 -> 65530 | E12: =IFERROR(IF(B12=0,0,D12/B12), 0) -> 6553 | F12: =IFERROR('P&L'!I30/1200, 0) -> 50 | G12: =IFERROR(IF(B12=0,0,F12/B12), 0) -> 5
A13: M8 | B13: ='Churn Model'!E36 -> 11 | C13: ='P&L'!J28-'P&L'!I28 -> 1 | D13: ='P&L'!J33 -> 72083 | E13: =IFERROR(IF(B13=0,0,D13/B13), 0) -> 6553 | F13: =IFERROR('P&L'!J30/1200, 0) -> 55 | G13: =IFERROR(IF(B13=0,0,F13/B13), 0) -> 5
A14: M9 | B14: ='Churn Model'!E37 -> 12 | C14: ='P&L'!K28-'P&L'!J28 -> 1 | D14: ='P&L'!K33 -> 78636 | E14: =IFERROR(IF(B14=0,0,D14/B14), 0) -> 6553 | F14: =IFERROR('P&L'!K30/1200, 0) -> 60 | G14: =IFERROR(IF(B14=0,0,F14/B14), 0) -> 5
A15: M10 | B15: ='Churn Model'!E38 -> 13 | C15: ='P&L'!L28-'P&L'!K28 -> 1 | D15: ='P&L'!L33 -> 85189 | E15: =IFERROR(IF(B15=0,0,D15/B15), 0) -> 6553 | F15: =IFERROR('P&L'!L30/1200, 0) -> 65 | G15: =IFERROR(IF(B15=0,0,F15/B15), 0) -> 5
A16: M11 | B16: ='Churn Model'!E39 -> 14 | C16: ='P&L'!M28-'P&L'!L28 -> 1 | D16: ='P&L'!M33 -> 91742 | E16: =IFERROR(IF(B16=0,0,D16/B16), 0) -> 6553 | F16: =IFERROR('P&L'!M30/1200, 0) -> 70 | G16: =IFERROR(IF(B16=0,0,F16/B16), 0) -> 5
A17: M12 | B17: ='Churn Model'!E40 -> 15 | C17: ='P&L'!N28-'P&L'!M28 -> 1 | D17: ='P&L'!N33 -> 98295 | E17: =IFERROR(IF(B17=0,0,D17/B17), 0) -> 6553 | F17: =IFERROR('P&L'!N30/1200, 0) -> 75 | G17: =IFERROR(IF(B17=0,0,F17/B17), 0) -> 5
A18: M13 | B18: ='Churn Model'!E41 -> 19 | C18: ='P&L'!O28-'P&L'!N28 -> 4 | D18: ='P&L'!O33 -> 124507 | E18: =IFERROR(IF(B18=0,0,D18/B18), 0) -> 6553 | F18: =IFERROR('P&L'!O30/1200, 0) -> 95 | G18: =IFERROR(IF(B18=0,0,F18/B18), 0) -> 5
A19: M14 | B19: ='Churn Model'!E42 -> 24 | C19: ='P&L'!P28-'P&L'!O28 -> 5 | D19: ='P&L'!P33 -> 157272 | E19: =IFERROR(IF(B19=0,0,D19/B19), 0) -> 6553 | F19: =IFERROR('P&L'!P30/1200, 0) -> 120 | G19: =IFERROR(IF(B19=0,0,F19/B19), 0) -> 5
A20: M15 | B20: ='Churn Model'!E43 -> 30 | C20: ='P&L'!Q28-'P&L'!P28 -> 6 | D20: ='P&L'!Q33 -> 196590 | E20: =IFERROR(IF(B20=0,0,D20/B20), 0) -> 6553 | F20: =IFERROR('P&L'!Q30/1200, 0) -> 150 | G20: =IFERROR(IF(B20=0,0,F20/B20), 0) -> 5
A21: M16 | B21: ='Churn Model'!E44 -> 38 | C21: ='P&L'!R28-'P&L'!Q28 -> 8 | D21: ='P&L'!R33 -> 249014 | E21: =IFERROR(IF(B21=0,0,D21/B21), 0) -> 6553 | F21: =IFERROR('P&L'!R30/1200, 0) -> 190 | G21: =IFERROR(IF(B21=0,0,F21/B21), 0) -> 5
A22: M17 | B22: ='Churn Model'!E45 -> 47 | C22: ='P&L'!S28-'P&L'!R28 -> 9 | D22: ='P&L'!S33 -> 307991 | E22: =IFERROR(IF(B22=0,0,D22/B22), 0) -> 6553 | F22: =IFERROR('P&L'!S30/1200, 0) -> 235 | G22: =IFERROR(IF(B22=0,0,F22/B22), 0) -> 5
A23: M18 | B23: ='Churn Model'!E46 -> 59 | C23: ='P&L'!T28-'P&L'!S28 -> 12 | D23: ='P&L'!T33 -> 386627 | E23: =IFERROR(IF(B23=0,0,D23/B23), 0) -> 6553 | F23: =IFERROR('P&L'!T30/1200, 0) -> 295 | G23: =IFERROR(IF(B23=0,0,F23/B23), 0) -> 5
A24: M19 | B24: ='Churn Model'!E47 -> 75 | C24: ='P&L'!U28-'P&L'!T28 -> 16 | D24: ='P&L'!U33 -> 491475 | E24: =IFERROR(IF(B24=0,0,D24/B24), 0) -> 6553 | F24: =IFERROR('P&L'!U30/1200, 0) -> 375 | G24: =IFERROR(IF(B24=0,0,F24/B24), 0) -> 5
A25: M20 | B25: ='Churn Model'!E48 -> 95 | C25: ='P&L'!V28-'P&L'!U28 -> 20 | D25: ='P&L'!V33 -> 622535 | E25: =IFERROR(IF(B25=0,0,D25/B25), 0) -> 6553 | F25: =IFERROR('P&L'!V30/1200, 0) -> 475 | G25: =IFERROR(IF(B25=0,0,F25/B25), 0) -> 5
A26: M21 | B26: ='Churn Model'!E49 -> 120 | C26: ='P&L'!W28-'P&L'!V28 -> 25 | D26: ='P&L'!W33 -> 786360 | E26: =IFERROR(IF(B26=0,0,D26/B26), 0) -> 6553 | F26: =IFERROR('P&L'!W30/1200, 0) -> 600 | G26: =IFERROR(IF(B26=0,0,F26/B26), 0) -> 5
A27: M22 | B27: ='Churn Model'!E50 -> 151 | C27: ='P&L'!X28-'P&L'!W28 -> 31 | D27: ='P&L'!X33 -> 989503 | E27: =IFERROR(IF(B27=0,0,D27/B27), 0) -> 6553 | F27: =IFERROR('P&L'!X30/1200, 0) -> 755 | G27: =IFERROR(IF(B27=0,0,F27/B27), 0) -> 5
A28: M23 | B28: ='Churn Model'!E51 -> 190 | C28: ='P&L'!Y28-'P&L'!X28 -> 39 | D28: ='P&L'!Y33 -> 1245070 | E28: =IFERROR(IF(B28=0,0,D28/B28), 0) -> 6553 | F28: =IFERROR('P&L'!Y30/1200, 0) -> 950 | G28: =IFERROR(IF(B28=0,0,F28/B28), 0) -> 5
A29: M24 | B29: ='Churn Model'!E52 -> 239 | C29: ='P&L'!Z28-'P&L'!Y28 -> 49 | D29: ='P&L'!Z33 -> 1566167 | E29: =IFERROR(IF(B29=0,0,D29/B29), 0) -> 6553 | F29: =IFERROR('P&L'!Z30/1200, 0) -> 1195 | G29: =IFERROR(IF(B29=0,0,F29/B29), 0) -> 5
A31: Data validation: Carrier counts now reflect churn impact

Sheet Scenario Analysis
A1: VELOCITYMATCH - SCENARIO ANALYSIS
A2: Best Case / Base Case / Worst Case Projections | Yellow cells are adjustable inputs
A4: SCENARIO PARAMETERS
A6: Parameter | B6: Worst Case | C6: Base Case | D6: Best Case | E6: Pessimistic | F6: Recession | G6: Unit | H6: Notes
A7: Starting Carriers | B7: =Assumptions!B144 -> 2 | C7: =Assumptions!B145 -> 4 | D7: =Assumptions!B146 -> 6 | E7: =Assumptions!B147 -> 3 | F7: =Assumptions!B148 -> 1 | G7: carriers | H7: Initial beta customers
A8: Monthly Growth Y1 | B8: =Assumptions!B149 -> 0.1 | C8: =Assumptions!B150 -> 0.15 | D8: =Assumptions!B151 -> 0.2 | E8: =Assumptions!B152 -> 0.08 | F8: =Assumptions!B153 -> 0.03 | G8: % | H8: Month-over-month growth
A9: Monthly Growth Y2 | B9: =Assumptions!B154 -> 0.15 | C9: =Assumptions!B155 -> 0.3 | D9: =Assumptions!B156 -> 0.4 | E9: =Assumptions!B157 -> 0.12 | F9: =Assumptions!B158 -> 0.05 | G9: % | H9: Scaling phase growth
A10: Monthly Churn Y1 | B10: =Assumptions!B159 -> 0.08 | C10: =Assumptions!B158 -> 0.05 | D10: =Assumptions!B153 -> 0.03 | E10: =Assumptions!B160 -> 0.1 | F10: =Assumptions!B161 -> 0.15 | G10: % | H10: Customer attrition
A11: Monthly Churn Y2 | B11: =Assumptions!B162 -> 0.06 | C11: =Assumptions!B163 -> 0.04 | D11: =Assumptions!B164 -> 0.02 | E11: =Assumptions!B165 -> 0.08 | F11: =Assumptions!B166 -> 0.12 | G11: % | H11: Improved retention
A12: Placements/Carrier | B12: 3 | C12: 5 | D12: 7 | E12: 4 | F12: 2 | G12: placements | H12: Average monthly placements
A13: Add-on Attach Rate | B13: =Assumptions!B167 -> 0.4 | C13: 0.6 | D13: 0.75 | E13: =Assumptions!B168 -> 0.3 | F13: =Assumptions!B169 -> 0.2 | G13: % | H13: Cross-sell success
A14: Placement Fee | B14: 1000 | C14: =Assumptions!B170 -> 1200 | D14: =Assumptions!B171 -> 1400 | E14: 1000 | F14: 800 | G14: $ | H14: Per-hire pricing
A15: Matching Engine Fee | B15: 249 | C15: =Assumptions!B172 -> 299 | D15: 349 | E15: 249 | F15: 199 | G15: $/month | H15: Core subscription
A18: SCENARIO OUTPUTS - 24 MONTH PROJECTIONS
A20: Metric | B20: Worst Case | C20: Base Case | D20: Best Case | G20: Notes
A21: Y1 Ending Carriers | B21: =ROUND(B7*(1+B8)^12*(1-B10)^12,0) -> 2 | C21: =ROUND(C7*(1+C8)^12*(1-C10)^12,0) -> 12 | D21: =ROUND(D7*(1+D8)^12*(1-D10)^12,0) -> 37 | G21: Net of growth and churn
A22: Y2 Ending Carriers | B22: =ROUND(B21*(1+B9)^12*(1-B11)^12,0) -> 5 | C22: =ROUND(C21*(1+C9)^12*(1-C11)^12,0) -> 171 | D22: =ROUND(D21*(1+D9)^12*(1-D11)^12,0) -> 1646 | G22: Second year projection
A23: Y1 Total Revenue | B23: =B21*12*(B14+B12*B15+B13*400) -> 45768 | C23: =C21*12*(C14+C12*C15+C13*400) -> 422640 | D23: =D21*12*(D14+D12*D15+D13*400) -> 1839492 | G23: Subscription + Placements + Add-ons
A24: Y2 Total Revenue | B24: =B22*12*(B14+B12*B15+B13*400) -> 114420 | C24: =C22*12*(C14+C12*C15+C13*400) -> 6022620 | D24: =D22*12*(D14+D12*D15+D13*400) -> 81832536 | G24: Second year revenue
A25: 24-Month Total Revenue | B25: =B23+B24 -> 160188 | C25: =C23+C24 -> 6445260 | D25: =D23+D24 -> 83672028 | G25: Combined two-year revenue
A26: Y1 Monthly Burn Rate | B26: =Assumptions!B173 -> 15000 | C26: =Assumptions!B174 -> 12000 | D26: =Assumptions!B175 -> 10000 | G26: Operating expenses (estimate)
A27: Runway Required (months) | B27: =IFERROR(IF(B26>0,ROUND('Startup Costs-Led BuildWA'!$B$90/B26,0),0), 0) -> 13 | C27: =IFERROR(IF(C26>0,ROUND('Startup Costs-Led BuildWA'!$B$90/C26,0),0), 0) -> 16 | D27: =IFERROR(IF(D26>0,ROUND('Startup Costs-Led BuildWA'!$B$90/D26,0),0), 0) -> 19 | G27: Capital needed pre-profitability
A30: BREAKEVEN ANALYSIS
A32: Scenario | B32: Est. Breakeven Month | C32: Monthly Revenue at BE | D32: Confidence Level
A33: Worst Case | B33: 24 | C33: =B26 -> 15000 | D33: Low (20%)
A34: Base Case | B34: 18 | C34: =C26 -> 12000 | D34: Medium (60%)
A35: Best Case | B35: 12 | C35: =D26 -> 10000 | D35: Aspirational (20%)

Sheet Platform Roadmap
A1: VELOCITYMATCH - PLATFORM ROADMAP
A2: 11-Layer Technology Stack Evolution (8 Core + 3 Expansion)
A4: Layer | B4: Name | C4: Description | D4: Key Features | E4: Revenue Streams | F4: Timeline | G4: Investment
A5: 1 | B5: AI Matching Engine | C5: Core driver-carrier matching algorithm | D5: ML matching, skill analysis, preference learning | E5: Per-Hire Fees, Matching Subscriptions, Usage-Based Credits | F5: M1-M6 (MVP) | G5: $187K
A6: 2 | B6: Data & Intelligence | C6: Monetizable insights and data services | D6: Market analytics, compensation benchmarking, turnover prediction | E6: Intelligence Subscriptions, API Access, Data Licenses | F6: M7-M12 | G6: $150K
A7: 3 | B7: Brokerage Automation | C7: Automates freight brokerage tasks | D7: Automated driver-carrier matching for freight brokers | E7: Per-Load Fees, Booking Fees, Automation Add-Ons | F7: M10-M15 | G7: $175K
A8: 4 | B8: Operations Automation | C8: Automates daily fleet and dispatch operations | D8: DQ file compliance, onboarding workflows, document mgmt | E8: Fleet SaaS Subscriptions, Workflow Automation, Predictive Maintenance | F8: M12-M18 | G8: $200K
A9: 5 | B9: Application Suite | C9: Interfaces for shippers, carriers, drivers, and recruiters | D9: Mobile apps, web dashboards, recruiter tools | E9: SaaS Subscriptions, LMS Seats, Training Modules | F9: M15-M21 | G9: $225K
A10: 6 | B10: Integrations | C10: Connections to TMS, ELDs, factoring, robotics, load boards | D10: API connections, data sync, webhook events | E10: Integration Fees, API Usage, Enterprise Implementation | F10: M18-M24 | G10: $250K
A11: 7 | B11: Analytics & Telematics | C11: Insights, behavior monitoring, performance dashboards | D11: ELD data ingestion, safety scores, driver behavior analytics | E11: Analytics Subscriptions, KPI Dashboards, Predictive Maintenance Intelligence | F11: M21-M30 | G11: $400K
A12: 8 | B12: Enterprise Control Layer | C12: Admin tools for billing, permissions, workflows | D12: Multi-location mgmt, SSO, admin controls, white-label | E12: Enterprise SaaS, Admin Add-Ons, Multi-Tenant Licensing | F12: M24-M36 | G12: $500K
A13: 9 | B13: Marketplace Platform | C13: Two-sided marketplace for drivers and carriers | D13: Carrier lead swap, Driver profiles, carrier listings, real-time availability matching | E13: Platform Fees, Premium Listings, Featured Placements | F13: M30-M42 | G13: $600K
A14: =Assumptions!B176 -> 10 | B14: Financial Services | C14: Embedded fintech for trucking ecosystem | D14: Factoring partnerships, fuel cards, equipment financing, insurance | E14: Referral Fees, Revenue Share, Embedded Finance Margins | F14: M36-M48 | G14: $750K
A15: 11 | B15: Network Effects Platform | C15: Multi-carrier coordination and capacity sharing | D15: Load sharing, driver pools, capacity networks, surge pricing | E15: Transaction Fees, Network Subscriptions, Capacity Premiums | F15: M42-M54 | G15: $900K
A18: INVESTMENT SUMMARY BY PHASE
A20: Phase | B20: Layers | C20: Total Investment | D20: Cumulative ARR Target | E20: Timeline
A21: Seed (Current) | B21: 1 | C21: =Assumptions!B177 -> 187974 | D21: $500K | E21: M1-M6
A22: Series A | B22: 2-4 | C22: =Assumptions!B178 -> 525000 | D22: $2M | E22: M7-M18
A23: Series B | B23: 5-8 | C23: =Assumptions!B179 -> 1375000 | D23: $10M | E23: M15-M36
A24: Series C | B24: 9-10 | C24: =Assumptions!B180 -> 1350000 | D24: $30M | E24: M30-M48
A25: Growth | B25: =Assumptions!B181 -> 11 | C25: =Assumptions!B182 -> 900000 | D25: $75M+ | E25: M42-M54
A28: LEGEND
A29: Green = Current Focus (Layer 1)
A30: Blue = Official Roadmap (Layers 2-8)
A31: Orange = Expansion Layers (Layers 9-11)
A33: TOTAL PLATFORM INVESTMENT: | B33: =Assumptions!B183 -> 4337974

Sheet Assumptions
A1: VELOCITYMATCH LAYER 1 - FINANCIAL MODEL ASSUMPTIONS
A2: AI Matching Engine Revenue Model
A3: Generated: December 17, 2025
A5: Category | B5: Assumption | C5: Value | D5: Unit | E5: Notes
A6: REVENUE MODEL
A7: Placement Pricing | B7: Per-Hire Placement Fee | C7: 1200 | D7: $ | E7: Core revenue per successful driver placement
A8: Placement Pricing | B8: Setup Fee (One-Time) | C8: 100 | D8: $ | E8: Initial carrier onboarding fee (included in placement)
A9: Placement Pricing | B9: Net Revenue per Placement | C9: 1200 | D9: $ | E9: Total revenue per completed placement
A10: Placement Pricing | B10: Matching Engine Subscription | C10: 299 | D10: $/month | E10: Core subscription fee for AI matching platform
A12: MARKET & GROWTH
A13: Market Size | B13: Total US CDL Drivers | C13: 3500000 | D13: drivers | E13: Addressable market (ATA 2024 data)
A14: Market Size | B14: Annual Driver Turnover | C14: 94 | D14: % | E14: Industry turnover rate (ATRI 2024)
A15: Market Size | B15: Annual Hiring Need | C15: 3290000 | D15: hires/year | E15: Market opportunity = 3.5M × 94%
A16: Growth Rates | B16: Year 1 Monthly Placement Growth | C16: 15 | D16: % | E16: Initial traction phase growth rate
A17: Growth Rates | B17: Year 2 Monthly Placement Growth | C17: 30 | D17: % | E17: Scaling phase with market validation (aligned with P&L)
A18: Growth Rates | B18: Year 3+ Monthly Placement Growth | C18: 25 | D18: % | E18: Full market penetration phase
A20: CUSTOMER ACQUISITION
A21: Driver Acquisition | B21: Driver CAC (Paid Ads) | C21: 16.28 | D21: $/lead | E21: Based on Last Mile campaign data (Dec 2025)
A22: Driver Acquisition | B22: Driver Conversion Rate | C22: 35 | D22: % | E22: Lead to completed onboarding
A23: Driver Acquisition | B23: Effective Driver CAC | C23: 46.51 | D23: $/driver | E23: CAC ÷ conversion rate
A24: Driver Acquisition | B24: Driver Lead Sources | C24: Meta Platform Ads, X, Google PPC, LinkedIn, Organic | E24: Multi-channel acquisition strategy
A26: Carrier Acquisition | B26: Carrier CAC (TMS SaaS Benchmark) | C26: 450 | D26: $/carrier | E26: Industry benchmark for TMS software
A27: Carrier Acquisition | B27: Carrier Onboarding Time | C27: 14 | D27: days | E27: Average time to first placement
A28: Carrier Acquisition | B28: Carriers per Sales Rep (Annual) | C28: 48 | D28: carriers | E28: Enterprise sales productivity
A29: Carrier Acquisition | B29: Average Fleet Size (Carriers) | C29: 125 | D29: trucks | E29: Target carrier profile
A31: UNIT ECONOMICS
A32: Placement Metrics | B32: Average Time to Placement | C32: 7 | D32: days | E32: From driver application to hire
A33: Placement Metrics | B33: Match Success Rate | C33: 85 | D33: % | E33: Successful placements vs attempts
A34: Placement Metrics | B34: Driver Retention (90-Day) | C34: 78 | D34: % | E34: Industry benchmark for quality placements
A35: Placement Metrics | B35: Replacement Guarantee Period | C35: 30 | D35: days | E35: Free replacement window
A37: Contribution Margin | B37: Revenue per Placement | C37: 1200 | D37: $ | E37: Gross revenue
A38: Contribution Margin | B38: Variable Costs per Placement | C38: 65 | D38: $ | E38: Driver CAC + processing + support
A39: Contribution Margin | B39: Contribution Margin per Unit | C39: 1135 | D39: $ | E39: Revenue - variable costs
A40: Contribution Margin | B40: Contribution Margin % | C40: 94.6 | D40: % | E40: (Revenue - COGS) ÷ Revenue
A42: OPERATING EXPENSES
A43: Technology Infrastructure | B43: Google Cloud Platform (Monthly) | C43: 1200 | D43: $/month | E43: Compute, storage, ML services, redundancy
A44: Technology Infrastructure | B44: Third-Party Services (Monthly) | C44: 250 | D44: $/month | E44: Twilio, SendGrid, authentication, monitoring
A45: Technology Infrastructure | B45: Development Tools (Monthly) | C45: 400 | D45: $/month | E45: GitHub, dev infrastructure, web dev
A47: Personnel (Founder Phase) | B47: Founder Salary (Minimal) | C47: 3500 | D47: $/month | E47: Bare minimum living expenses
A48: Personnel (Founder Phase) | B48: Contract Developers (as needed) | C48: 85 | D48: $/hour | E48: Specialized development work
...

Sheet Churn Model
A1: VELOCITYMATCH - CARRIER CHURN & RETENTION MODEL
A2: Customer Lifecycle Analysis | Yellow cells are inputs
A3: Generated: December 23, 2025
A5: CHURN ASSUMPTIONS
A6: Input | B6: Value | C6: Unit | D6: Notes | E6: Industry Benchmark
A7: Monthly Churn Rate (Y1) | B7: ='Scenario Analysis'!C10 -> 0.05 | C7: % | D7: Expected monthly carrier churn | E7: 5-7% for SaaS
A8: Monthly Churn Rate (Y2) | B8: ='Scenario Analysis'!C11 -> 0.04 | C8: % | D8: Improved with product maturity | E8: 3-5% for established
A9: Monthly Churn Rate (Y3+) | B9: =Assumptions!B153 -> 0.03 | C9: % | D9: Stable mature product | E9: 2-4% best-in-class
A10: Reactivation Rate | B10: =Assumptions!B184 -> 0.1 | C10: % | D10: Churned carriers who return | E10: 5-15% industry avg
A13: RETENTION & LIFETIME VALUE METRICS
A14: Metric | B14: Value | C14: Formula | D14: Notes
A15: Monthly Retention Rate (Y1) | B15: =1-B7 -> 0.95 | C15: =1 - Churn Rate -> #NAME? | D15: 95% retention monthly
A16: Annual Retention Rate (Y1) | B16: =B15^12 -> 0.54036009 | C16: =Monthly^12 -> #NAME? | D16: Compounded annual retention
A17: Customer Lifetime (months) | B17: =IFERROR(1/B7, "N/A") -> 20 | C17: =IFERROR(1 / Churn Rate, 0) -> 0 | D17: Average months before churn
A18: Revenue per Carrier/Month | B18: =Assumptions!B185 -> 6553 | C18: From P&L model | D18: Matching + Placements + Add-ons
A19: Customer Lifetime Value (LTV) | B19: =B17*B18 -> 131060 | C19: =Lifetime x Revenue -> #NAME? | D19: Total revenue per carrier
A20: Carrier Acquisition Cost (CAC) | B20: 450 | C20: From Assumptions | D20: TMS SaaS benchmark
A21: LTV:CAC Ratio | B21: =IFERROR(B19/B20, 0) -> 291.24444 | C21: =IFERROR(LTV / CAC, 0) -> 0 | D21: Target: >3:1 for healthy SaaS
A22: CAC Payback (months) | B22: =IFERROR(B20/B18, 0) -> 0.068670838 | C22: =IFERROR(CAC / Monthly Revenue, 0) -> 0 | D22: Target: <12 months
A25: CARRIER COHORT ANALYSIS - WITH CHURN
A26: Shows how churn impacts carrier count vs. P&L gross projections
A28: Month | B28: New Carriers | C28: Churned | D28: Retained | E28: Net Active | F28: Gross (No Churn) | G28: Churn Impact
A29: M1 | B29: 4 | C29: 0 | D29: 0 | E29: =B29 -> 4 | F29: 4 | G29: =F29-E29 -> 0
A30: M2 | B30: =MAX(1,ROUND(E29*0.15,0)) -> 1 | C30: =ROUND(E29*$B$7,0) -> 0 | D30: =E29-C30 -> 4 | E30: =B30+D30 -> 5 | F30: =ROUND(F29*1.15,0) -> 5 | G30: =F30-E30 -> 0
A31: M3 | B31: =MAX(1,ROUND(E30*0.15,0)) -> 1 | C31: =ROUND(E30*$B$7,0) -> 0 | D31: =E30-C31 -> 5 | E31: =B31+D31 -> 6 | F31: =ROUND(F30*1.15,0) -> 6 | G31: =F31-E31 -> 0
A32: M4 | B32: =MAX(1,ROUND(E31*0.15,0)) -> 1 | C32: =ROUND(E31*$B$7,0) -> 0 | D32: =E31-C32 -> 6 | E32: =B32+D32 -> 7 | F32: =ROUND(F31*1.15,0) -> 7 | G32: =F32-E32 -> 0
A33: M5 | B33: =MAX(1,ROUND(E32*0.15,0)) -> 1 | C33: =ROUND(E32*$B$7,0) -> 0 | D33: =E32-C33 -> 7 | E33: =B33+D33 -> 8 | F33: =ROUND(F32*1.15,0) -> 8 | G33: =F33-E33 -> 0
A34: M6 | B34: =MAX(1,ROUND(E33*0.15,0)) -> 1 | C34: =ROUND(E33*$B$7,0) -> 0 | D34: =E33-C34 -> 8 | E34: =B34+D34 -> 9 | F34: =ROUND(F33*1.15,0) -> 9 | G34: =F34-E34 -> 0
A35: M7 | B35: =MAX(1,ROUND(E34*0.15,0)) -> 1 | C35: =ROUND(E34*$B$7,0) -> 0 | D35: =E34-C35 -> 9 | E35: =B35+D35 -> 10 | F35: =ROUND(F34*1.15,0) -> 10 | G35: =F35-E35 -> 0
A36: M8 | B36: =MAX(1,ROUND(E35*0.15,0)) -> 2 | C36: =ROUND(E35*$B$7,0) -> 1 | D36: =E35-C36 -> 9 | E36: =B36+D36 -> 11 | F36: =ROUND(F35*1.15,0) -> 12 | G36: =F36-E36 -> 1
A37: M9 | B37: =MAX(1,ROUND(E36*0.15,0)) -> 2 | C37: =ROUND(E36*$B$7,0) -> 1 | D37: =E36-C37 -> 10 | E37: =B37+D37 -> 12 | F37: =ROUND(F36*1.15,0) -> 14 | G37: =F37-E37 -> 2
A38: M10 | B38: =MAX(1,ROUND(E37*0.15,0)) -> 2 | C38: =ROUND(E37*$B$7,0) -> 1 | D38: =E37-C38 -> 11 | E38: =B38+D38 -> 13 | F38: =ROUND(F37*1.15,0) -> 16 | G38: =F38-E38 -> 3
A39: M11 | B39: =MAX(1,ROUND(E38*0.15,0)) -> 2 | C39: =ROUND(E38*$B$7,0) -> 1 | D39: =E38-C39 -> 12 | E39: =B39+D39 -> 14 | F39: =ROUND(F38*1.15,0) -> 18 | G39: =F39-E39 -> 4
A40: M12 | B40: =MAX(1,ROUND(E39*0.15,0)) -> 2 | C40: =ROUND(E39*$B$7,0) -> 1 | D40: =E39-C40 -> 13 | E40: =B40+D40 -> 15 | F40: =ROUND(F39*1.15,0) -> 21 | G40: =F40-E40 -> 6
A41: M13 | B41: =MAX(1,ROUND(E40*0.3,0)) -> 5 | C41: =ROUND(E40*$B$8,0) -> 1 | D41: =E40-C41 -> 14 | E41: =B41+D41 -> 19 | F41: =ROUND(F40*1.3,0) -> 27 | G41: =F41-E41 -> 8
A42: M14 | B42: =MAX(1,ROUND(E41*0.3,0)) -> 6 | C42: =ROUND(E41*$B$8,0) -> 1 | D42: =E41-C42 -> 18 | E42: =B42+D42 -> 24 | F42: =ROUND(F41*1.3,0) -> 35 | G42: =F42-E42 -> 11
A43: M15 | B43: =MAX(1,ROUND(E42*0.3,0)) -> 7 | C43: =ROUND(E42*$B$8,0) -> 1 | D43: =E42-C43 -> 23 | E43: =B43+D43 -> 30 | F43: =ROUND(F42*1.3,0) -> 46 | G43: =F43-E43 -> 16
A44: M16 | B44: =MAX(1,ROUND(E43*0.3,0)) -> 9 | C44: =ROUND(E43*$B$8,0) -> 1 | D44: =E43-C44 -> 29 | E44: =B44+D44 -> 38 | F44: =ROUND(F43*1.3,0) -> 60 | G44: =F44-E44 -> 22
A45: M17 | B45: =MAX(1,ROUND(E44*0.3,0)) -> 11 | C45: =ROUND(E44*$B$8,0) -> 2 | D45: =E44-C45 -> 36 | E45: =B45+D45 -> 47 | F45: =ROUND(F44*1.3,0) -> 78 | G45: =F45-E45 -> 31
A46: M18 | B46: =MAX(1,ROUND(E45*0.3,0)) -> 14 | C46: =ROUND(E45*$B$8,0) -> 2 | D46: =E45-C46 -> 45 | E46: =B46+D46 -> 59 | F46: =ROUND(F45*1.3,0) -> 101 | G46: =F46-E46 -> 42
...

Sheet Startup Costs-Led BuildWA
A1: VELOCITYMATCH LAYER 1 STARTUP COSTS - FOUNDER-LED MVP
A2: Strategic Focus: Solo Founder Builds Layer 1 (AI Matching Engine) - Google Cloud Platform
A3: Generated: December 17, 2025
A5: Category | B5: Line Item | C5: Description | D5: Quantity | E5: Unit Cost | F5: Total Cost | G5: Timing | H5: Notes/Assumptions
A6: Technology & Development | B6: Google Cloud Platform - Infrastructure | C6: GCP setup: Compute Engine, Cloud SQL, Cloud Storage, Vertex AI | D6: 1 | E6: =Assumptions!B187 -> 22000 | F6: =Assumptions!B187 -> 22000 | G6: Months 1-6 | H6: GCP for dev/staging/prod + ML infrastructure, founder DevOps
A7: Technology & Development | B7: Mobile Development (Contract) | C7: React Native app for driver onboarding - iOS/Android | D7: 1 | E7: =Assumptions!B188 -> 35000 | F7: =Assumptions!B188 -> 35000 | G7: Months 3-5 | H7: Contractor builds mobile while founder focuses on ML core
A8: Technology & Development | B8: UI/UX Design (Contract) | C8: Design system, driver app UX, carrier dashboard design | D8: 1 | E8: =Assumptions!B189 -> 18000 | F8: =Assumptions!B189 -> 18000 | G8: Months 2-4 | H8: Professional design contractor - founder implements
A9: Technology & Development | B9: AI/ML Training Data & Tools | C9: Synthetic data generation, labeling tools, model training costs | D9: 1 | E9: =Assumptions!B190 -> 8000 | F9: =Assumptions!B190 -> 8000 | G9: Months 1-4 | H9: Data prep for matching algorithm training
A10: Technology & Development | B10: Development Tools & Licenses | C10: GitHub, Linear, Figma, GCP credits, AI/ML tools | D10: 6 | E10: 400 | F10: =Assumptions!B191 -> 2400 | G10: Months 1-6 | H10: Solo founder toolset - lean but professional
A11: Technology & Development | B11: API & Integration Services | C11: Twilio, SendGrid, authentication services, payment processing | D11: 6 | E11: 250 | F11: =Assumptions!B192 -> 1500 | G11: Months 1-6 | H11: Essential third-party services for MVP
A12: Legal & Compliance | B12: Business Formation & Registration | C12: LLC formation, state registration, EIN | D12: 1 | E12: =Assumptions!B193 -> 2000 | F12: =Assumptions!B193 -> 2000 | G12: Month 1 | H12: DIY formation with LegalZoom + attorney review
A13: Legal & Compliance | B13: Freight Broker Authority (MC Number) | C13: FMCSA operating authority, BOC-3 filing | D13: 1 | E13: =Assumptions!B194 -> 2500 | F13: =Assumptions!B194 -> 2500 | G13: Month 1 | H13: Required for freight brokerage operations
A14: Legal & Compliance | B14: Surety Bond | C14: $75k freight broker bond (required by FMCSA) | D14: 1 | E14: =Assumptions!B195 -> 1200 | F14: =Assumptions!B195 -> 1200 | G14: Month 1 | H14: Annual premium ~1.5-2% of bond amount
A15: Legal & Compliance | B15: Business Insurance Package | C15: General liability, cyber liability, E&O bundled | D15: 6 | E15: 650 | F15: =Assumptions!B196 -> 3900 | G15: Months 1-6 | H15: Small business insurance bundle ~$650/month
A16: Legal & Compliance | B16: Legal Templates & Compliance | C16: ToS, Privacy Policy, MSA templates, GDPR/CCPA basics | D16: 1 | E16: =Assumptions!B197 -> 3500 | F16: =Assumptions!B197 -> 3500 | G16: Month 2 | H16: Template package + attorney review - no custom drafting
A17: Legal & Compliance | B17: Trademark Filing (DIY) | C17: USPTO trademark filing for VelocityMatch | D17: 1 | E17: 750 | F17: 750 | G17: Month 2 | H17: DIY filing with online guidance
A18: Pilot Program & Validation | B18: Initial Carrier Outreach | C18: Beta carrier recruitment: LinkedIn, cold outreach, referrals | D18: 1 | E18: =Assumptions!B198 -> 3000 | F18: =Assumptions!B198 -> 3000 | G18: Months 3-5 | H18: Founder-led sales + small incentives for early adopters
A19: Pilot Program & Validation | B19: Driver Recruitment - Organic | C19: Recruit 30-50 drivers: Facebook groups, referrals, job boards | D19: 1 | E19: =Assumptions!B199 -> 5000 | F19: =Assumptions!B199 -> 5000 | G19: Months 4-6 | H19: Organic + minimal paid ads, founder-managed
A20: Pilot Program & Validation | B20: Beta Testing Tools | C20: UserTesting.com, survey tools, feedback management | D20: 1 | E20: =Assumptions!B200 -> 2500 | F20: =Assumptions!B200 -> 2500 | G20: Months 4-6 | H20: DIY user research with affordable tools
A21: Pilot Program & Validation | B21: Market Research & Data | C21: Industry reports, carrier interviews, competitive intel | D21: 1 | E21: =Assumptions!B201 -> 2000 | F21: =Assumptions!B201 -> 2000 | G21: Months 1-2 | H21: Free resources + 1-2 paid reports
A22: Brand & Marketing Foundation | B22: Brand Identity (DIY + Contractor) | C22: Logo design, basic brand guidelines | D22: 1 | E22: =Assumptions!B197 -> 3500 | F22: =Assumptions!B197 -> 3500 | G22: Month 1 | H22: Fiverr/99designs logo + founder creates guidelines
A23: Brand & Marketing Foundation | B23: Website (No-Code) | C23: Webflow/Framer marketing site with lead capture | D23: 1 | E23: =Assumptions!B202 -> 5000 | F23: =Assumptions!B202 -> 5000 | G23: Months 2-3 | H23: No-code platform + founder builds + template
A24: Brand & Marketing Foundation | B24: Sales Deck & Collateral | C24: Pitch deck, one-pager, founder creates in Figma | D24: 1 | E24: =Assumptions!B192 -> 1500 | F24: =Assumptions!B192 -> 1500 | G24: Month 3 | H24: DIY with design template + minor contractor help
A25: Brand & Marketing Foundation | B25: Demo Environment | C25: Sandbox GCP instance with seed data | D25: 1 | E25: =Assumptions!B201 -> 2000 | F25: =Assumptions!B201 -> 2000 | G25: Month 4 | H25: Founder-built demo with scripted scenarios
A26: Brand & Marketing Foundation | B26: Content Creation (Founder) | C26: LinkedIn posts, blog articles, thought leadership | D26: 1 | E26: 500 | F26: 500 | G26: Months 3-6 | H26: Founder writes, Grammarly edits, ChatGPT assists
A27: Operational Infrastructure | B27: Google Cloud Platform (GCP) | C27: Hosting, compute, storage, ML services | D27: 6 | E27: =Assumptions!B203 -> 1200 | F27: =Assumptions!B204 -> 7200 | G27: Months 1-6 | H27: Aggressive use of GCP startup credits + optimization
A28: Operational Infrastructure | B28: Software & Productivity Tools | C28: Notion, Slack free tier, Google Workspace | D28: 6 | E28: 150 | F28: 900 | G28: Months 1-6 | H28: Solo founder using mostly free tiers
A29: Operational Infrastructure | B29: Equipment (Personal) | C29: MacBook Pro upgrade if needed | D29: 1 | E29: =Assumptions!B205 -> 2500 | F29: =Assumptions!B205 -> 2500 | G29: Month 1 | H29: Use existing equipment or minimal upgrade
A30: Operational Infrastructure | B30: Virtual Office | C30: Virtual business address for LLC | D30: 6 | E30: 99 | F30: 594 | G30: Months 1-6 | H30: iPostal1 or similar budget virtual office
A31: Operational Infrastructure | B31: Accounting Software | C31: QuickBooks Self-Employed or Wave (free) | D31: 6 | E31: 30 | F31: 180 | G31: Months 1-6 | H31: DIY bookkeeping with affordable software
A32: Operational Infrastructure | B32: Business Phone | C32: Google Voice or basic VoIP | D32: 6 | E32: 25 | F32: 150 | G32: Months 1-6 | H32: Virtual phone number for professional presence
A33: Founder Living Expenses | B33: Founder Minimal Salary | C33: Bare minimum living expenses during build | D33: 6 | E33: =Assumptions!B197 -> 3500 | F33: =Assumptions!B206 -> 21000 | G33: Months 1-6 | H33: Ramen profitability - cut all non-essentials
A34: Founder Living Expenses | B34: Healthcare (Individual) | C34: Marketplace health insurance or spouse coverage | D34: 6 | E34: 400 | F34: =Assumptions!B207 -> 2400 | G34: Months 1-6 | H34: High-deductible plan to minimize monthly cost
A35: Founder Living Expenses | B35: Payroll Taxes (Self-Employment) | C35: Self-employment tax on minimal salary | D35: 1 | E35: =Assumptions!B208 -> 3300 | F35: =Assumptions!B208 -> 3300 | G35: Months 1-6 | H35: ~15.3% of salary for self-employment tax
A36: Contingency & Reserves | B36: Development Contingency | C36: 10% buffer for technical surprises | D36: 1 | E36: =Assumptions!B209 -> 9000 | F36: =Assumptions!B209 -> 9000 | G36: As Needed | H36: Smaller buffer - founder can pivot quickly
A37: Contingency & Reserves | B37: Emergency Fund | C37: Unexpected expenses or opportunities | D37: 1 | E37: =Assumptions!B210 -> 15000 | F37: =Assumptions!B210 -> 15000 | G37: As Needed | H37: Safety net for critical issues
A39: CATEGORY SUBTOTALS
A40: Technology & Development | F40: =Assumptions!B211 -> 86900
A41: Legal & Compliance | F41: =Assumptions!B212 -> 13850
A42: Pilot Program & Validation | F42: =Assumptions!B213 -> 12500
...

Sheet Revenue Model Overview
A1: VELOCITYMATCH LAYER 1 - REVENUE MODEL
A2: Complete Product & Pricing Structure
A3: Generated: December 22, 2025 | Research-Backed Pricing
B5: Product | C5: Price | D5: Model | E5: Includes | F5: Buyer | G5: Recurring | H5: One-Time
A6: 1 | B6: Matching Engine (Core) | C6: $299/mo | D6: Flat Monthly | E6: AI driver-carrier matching, 10 matches/month included | F6: Carriers, Recruiters | G6: X
A7: 2 | B7: Placement Services | C7: $1,200/placement | D7: Per-Hire Fee | E7: Full-service driver placement, screening, onboarding support | F7: Carriers, Recruiters | H7: X
A8: 3 | B8: Data & Intelligence | C8: $199/mo | D8: Add-On | E8: Market analytics, compensation benchmarking, turnover prediction | F8: Carriers, Recruiters | G8: X
A9: 4 | B9: Brokerage Automation | C9: $399/mo | D9: Flat Monthly | E9: Automated driver-carrier matching for freight brokers | F9: Brokers | G9: X
A10: 5 | B10: Operations Automation | C10: $249/mo | D10: Add-On | E10: Onboarding workflows, DQ file compliance, lightweight dispatch | F10: Carriers | G10: X
A11: 6 | B11: Carrier HR Dashboard | C11: $149/mo | D11: Flat Monthly | E11: Recruiting dashboard, applicant tracking, candidate management | F11: Carriers | G11: X
A12: 7 | B12: Integrations Bundle | C12: $199/mo | D12: Bundle | E12: 3 integrations included (TMS, HRIS/Payroll, ELD connectors) | F12: Carriers | G12: X
A13: 8 | B13: Analytics & Telematics | C13: $499-$999/mo | D13: Tiered | E13: ELD data ingestion, safety scores, driver behavior analytics | F13: Carriers | G13: X
A14: 9 | B14: Enterprise Control Layer | C14: $499/mo | D14: Add-On | E14: Multi-location/fleet mgmt, SSO, admin controls, permissions | F14: Enterprise Carriers | G14: X
A17: TIERED PRICING DETAILS
A19: Analytics & Telematics Tiers
A20: Tier | B20: Fleet Size | C20: Monthly Price | D20: Per-Truck Equivalent
A21: Standard | B21: Up to 100 trucks | C21: $499/mo | D21: $4.99/truck
A22: Professional | B22: 100-250 trucks | C22: $999/mo | D22: $4.00-$9.99/truck
A23: Enterprise | B23: 250+ trucks | C23: Custom | D23: Contact Sales
A26: OVERAGE PRICING (One-Time, As-Needed)
A28: Product | B28: Base Included | C28: Overage Rate | D28: Example
A29: Matching Engine | B29: 10 matches/month | C29: $35/additional match | D29: 15 matches = $299 + (5 x $35) = $474
A30: API Calls | B30: 10,000 calls/month | C30: $0.005/call after limit | D30: 25,000 calls = base + (15K x $0.005) = $75 overage
A31: Analytics & Telematics | B31: Tier truck limit | C31: $8/truck/month beyond tier | D31: Standard tier + 20 extra trucks = $499 + $160 = $659
A34: COST OF GOODS SOLD (COGS)
A36: Product | B36: Variable Cost | C36: Description | D36: Margin
A37: Matching Engine | B37: $15/mo | C37: LLM API costs (OpenAI/Anthropic), compute | D37: 95%
A38: Placement Services | B38: $65/placement | C38: Driver CAC ($46.51) + processing + support | D38: 94.6%
A39: Data & Intelligence | B39: $10/mo | C39: Data storage, third-party data feeds | D39: 95%
A40: Brokerage Automation | B40: $20/mo | C40: API costs, compute | D40: 95%
A41: Operations Automation | B41: $12/mo | C41: Document processing, storage | D41: 95%
A42: Carrier HR Dashboard | B42: $8/mo | C42: Hosting, support allocation | D42: 94.6%
A43: Integrations Bundle | B43: $25/mo | C43: Third-party API fees, maintenance | D43: 87.4%
A44: Analytics & Telematics | B44: $50-$100/mo | C44: ELD API fees, data processing, storage | D44: 80-90%
A45: Enterprise Control Layer | B45: $30/mo | C45: SSO providers, enhanced security | D45: 94%

Sheet Operating Expenses
A1: VELOCITYMATCH - OPERATING EXPENSES MODEL
A2: Dynamic Model - Yellow cells are inputs you can modify
A3: Generated: December 22, 2025
A5: INPUT ASSUMPTIONS
A6: Category | B6: Item | C6: Value | D6: Unit | E6: Notes
A7: Personnel | B7: Founder Monthly Salary | C7: =Assumptions!B217 -> 3500 | D7: $/month | E7: Lean founder salary
A8: Personnel | B8: Biz Dev Base Salary (Annual) | C8: =Assumptions!B218 -> 50000 | D8: $/year | E8: B2B carrier sales + driver retention
A9: Personnel | B9: Biz Dev Commission Rate | C9: 0.12 | D9: % | E9: 12% of first-year carrier revenue
A10: Personnel | B10: Biz Dev Start Month | C10: 3 | D10: month | E10: Staggered hiring
A11: Personnel | B11: Recruiter Hourly Rate | C11: 15 | D11: $/hour | E11: Part-time, you train up
A12: Personnel | B12: Recruiter Hours/Week | C12: 20 | D12: hours | E12: Part-time
A13: Personnel | B13: Recruiter Start Month | C13: 7 | D13: month | E13: Month 6-8 range
A14: Personnel | B14: Contract Dev Hourly Rate | C14: 85 | D14: $/hour | E14: Specialized development
A15: Personnel | B15: Contract Dev Hours/Month | C15: 40 | D15: hours | E15: As needed for key features
A16: Technology | B16: Google Cloud Platform | C16: =Assumptions!B219 -> 1200 | D16: $/month | E16: Compute, storage, ML services
A17: Technology | B17: Third-Party Services | C17: 250 | D17: $/month | E17: Twilio, SendGrid, auth
A18: Technology | B18: Development Tools | C18: 400 | D18: $/month | E18: GitHub, Linear, Figma
A19: Marketing | B19: Carrier Sales/Outreach | C19: =Assumptions!B202 -> 5000 | D19: $/month | E19: LinkedIn Sales Nav, prospecting, trade shows, outreach
A20: Marketing | B20: Driver Marketing | C20: =Assumptions!B220 -> 3000 | D20: $/month | E20: Facebook, job boards, digital ads
A21: G&A | B21: Business Insurance | C21: 650 | D21: $/month | E21: GL, cyber, E&O bundle
A22: G&A | B22: Legal/Compliance | C22: 500 | D22: $/month | E22: Retainer + surety bond amortized
A23: G&A | B23: Virtual Office | C23: 99 | D23: $/month | E23: Business address
A24: G&A | B24: Accounting Software | C24: 30 | D24: $/month | E24: QuickBooks
A25: G&A | B25: Business Phone | C25: 25 | D25: $/month | E25: Google Voice/VoIP
A26: G&A | B26: Healthcare (Founder) | C26: 400 | D26: $/month | E26: High-deductible plan
A27: G&A | B27: Payroll Tax Rate | C27: 0.153 | D27: % | E27: 15.3% self-employment / employer taxes
A30: MONTHLY OPERATING EXPENSES - YEAR 1
A32: Category | B32: Expense Item | C32: M1 | D32: M2 | E32: M3 | F32: M4 | G32: M5 | H32: M6 | I32: M7 | J32: M8 | K32: M9 | L32: M10 | M32: M11 | N32: M12 | O32: Y1 Total
A33: Personnel | B33: Founder Salary | C33: =$C$7 -> 3500 | D33: =$C$7 -> 3500 | E33: =$C$7 -> 3500 | F33: =$C$7 -> 3500 | G33: =$C$7 -> 3500 | H33: =$C$7 -> 3500 | I33: =$C$7 -> 3500 | J33: =$C$7 -> 3500 | ... N33: =$C$7 -> 3500 | O33: =SUM(C33:N33) -> 42000
A34: Personnel | B34: Biz Dev Base | C34: =IFERROR(IF(COLUMN()-2>=$C$10,$C$8/12,0), 0) -> 0 | D34: =IFERROR(IF(COLUMN()-2>=$C$10,$C$8/12,0), 0) -> 0 | E34: =IFERROR(IF(COLUMN()-2>=$C$10,$C$8/12,0), 0) -> 4166.6667 | F34: =IFERROR(IF(COLUMN()-2>=$C$10,$C$8/12,0), 0) -> 4166.6667 | G34: =IFERROR(IF(COLUMN()-2>=$C$10,$C$8/12,0), 0) -> 4166.6667 | H34: =IFERROR(IF(COLUMN()-2>=$C$10,$C$8/12,0), 0) -> 4166.6667 | I34: =IFERROR(IF(COLUMN()-2>=$C$10,$C$8/12,0), 0) -> 4166.6667 | J34: =IFERROR(IF(COLUMN()-2>=$C$10,$C$8/12,0), 0) -> 4166.6667 | ... N34: =IFERROR(IF(COLUMN()-2>=$C$10,$C$8/12,0), 0) -> 4166.6667 | O34: =SUM(C34:N34) -> 41666.667
A35: Personnel | B35: Biz Dev Commission | C35: =0 -> 0 | D35: =0 -> 0 | E35: =0 -> 0 | F35: =0 -> 0 | G35: =0 -> 0 | H35: =0 -> 0 | I35: =0 -> 0 | J35: =0 -> 0 | ... N35: =0 -> 0 | O35: =SUM(C35:N35) -> 0
A36: Personnel | B36: Part-Time Recruiter | C36: =IF(COLUMN()-2>=$C$13,$C$11*$C$12*4,0) -> 0 | D36: =IF(COLUMN()-2>=$C$13,$C$11*$C$12*4,0) -> 0 | E36: =IF(COLUMN()-2>=$C$13,$C$11*$C$12*4,0) -> 0 | F36: =IF(COLUMN()-2>=$C$13,$C$11*$C$12*4,0) -> 0 | G36: =IF(COLUMN()-2>=$C$13,$C$11*$C$12*4,0) -> 0 | H36: =IF(COLUMN()-2>=$C$13,$C$11*$C$12*4,0) -> 0 | I36: =IF(COLUMN()-2>=$C$13,$C$11*$C$12*4,0) -> 1200 | J36: =IF(COLUMN()-2>=$C$13,$C$11*$C$12*4,0) -> 1200 | ... N36: =IF(COLUMN()-2>=$C$13,$C$11*$C$12*4,0) -> 1200 | O36: =SUM(C36:N36) -> 7200
A37: Personnel | B37: Contract Developers | C37: =$C$14*$C$15 -> 3400 | D37: =$C$14*$C$15 -> 3400 | E37: =$C$14*$C$15 -> 3400 | F37: =$C$14*$C$15 -> 3400 | G37: =$C$14*$C$15 -> 3400 | H37: =$C$14*$C$15 -> 3400 | I37: =$C$14*$C$15 -> 3400 | J37: =$C$14*$C$15 -> 3400 | ... N37: =$C$14*$C$15 -> 3400 | O37: =SUM(C37:N37) -> 40800
A38: Personnel | B38: Payroll Taxes | C38: =(C33+C34+C36)*$C$27 -> 535.5 | D38: =(D33+D34+D36)*$C$27 -> 535.5 | E38: =(E33+E34+E36)*$C$27 -> 1173 | F38: =(F33+F34+F36)*$C$27 -> 1173 | G38: =(G33+G34+G36)*$C$27 -> 1173 | H38: =(H33+H34+H36)*$C$27 -> 1173 | I38: =(I33+I34+I36)*$C$27 -> 1356.6 | J38: =(J33+J34+J36)*$C$27 -> 1356.6 | ... N38: =(N33+N34+N36)*$C$27 -> 1356.6 | O38: =SUM(C38:N38) -> 13902.6
A39: Technology | B39: Google Cloud Platform | C39: =$C$16 -> 1200 | D39: =$C$16 -> 1200 | E39: =$C$16 -> 1200 | F39: =$C$16 -> 1200 | G39: =$C$16 -> 1200 | H39: =$C$16 -> 1200 | I39: =$C$16 -> 1200 | J39: =$C$16 -> 1200 | ... N39: =$C$16 -> 1200 | O39: =SUM(C39:N39) -> 14400
A40: Technology | B40: Third-Party Services | C40: =$C$17 -> 250 | D40: =$C$17 -> 250 | E40: =$C$17 -> 250 | F40: =$C$17 -> 250 | G40: =$C$17 -> 250 | H40: =$C$17 -> 250 | I40: =$C$17 -> 250 | J40: =$C$17 -> 250 | ... N40: =$C$17 -> 250 | O40: =SUM(C40:N40) -> 3000
A41: Technology | B41: Development Tools | C41: =$C$18 -> 400 | D41: =$C$18 -> 400 | E41: =$C$18 -> 400 | F41: =$C$18 -> 400 | G41: =$C$18 -> 400 | H41: =$C$18 -> 400 | I41: =$C$18 -> 400 | J41: =$C$18 -> 400 | ... N41: =$C$18 -> 400 | O41: =SUM(C41:N41) -> 4800
A42: Marketing | B42: Carrier Sales/Outreach | C42: =$C$19 -> 5000 | D42: =$C$19 -> 5000 | E42: =$C$19 -> 5000 | F42: =$C$19 -> 5000 | G42: =$C$19 -> 5000 | H42: =$C$19 -> 5000 | I42: =$C$19 -> 5000 | J42: =$C$19 -> 5000 | ... N42: =$C$19 -> 5000 | O42: =SUM(C42:N42) -> 60000
A43: Marketing | B43: Driver Marketing | C43: =$C$20 -> 3000 | D43: =$C$20 -> 3000 | E43: =$C$20 -> 3000 | F43: =$C$20 -> 3000 | G43: =$C$20 -> 3000 | H43: =$C$20 -> 3000 | I43: =$C$20 -> 3000 | J43: =$C$20 -> 3000 | ... N43: =$C$20 -> 3000 | O43: =SUM(C43:N43) -> 36000
A44: G&A | B44: Business Insurance | C44: =$C$21 -> 650 | D44: =$C$21 -> 650 | E44: =$C$21 -> 650 | F44: =$C$21 -> 650 | G44: =$C$21 -> 650 | H44: =$C$21 -> 650 | I44: =$C$21 -> 650 | J44: =$C$21 -> 650 | ... N44: =$C$21 -> 650 | O44: =SUM(C44:N44) -> 7800
...

Sheet P&L
A1: VELOCITYMATCH - PROFIT & LOSS STATEMENT
A2: 24-Month Projection | Yellow cells are modifiable inputs
A3: Generated: December 22, 2025
A4: NOTE: Active Carriers now pulled from Churn Model (includes churn impact)
A5: REVENUE ASSUMPTIONS
A6: Input | B6: Value | C6: Unit | D6: Notes
A7: Starting Carriers (Month 1) | B7: =Assumptions!B221 -> 4 | C7: carriers | D7: Initial beta customers
A8: Monthly Carrier Growth Rate (Y1) | B8: =Assumptions!B161 -> 0.15 | C8: % | D8: 15% month-over-month growth
A9: Monthly Carrier Growth Rate (Y2) | B9: =Assumptions!B222 -> 0.3 | C9: % | D9: 20% month-over-month growth
A10: Placements per Carrier per Month | B10: 5 | C10: placements | D10: Avg placements per active carrier
A11: Matching Engine Price | B11: =Assumptions!B172 -> 299 | C11: $/month | D11: Core subscription
A12: Placement Fee | B12: =Assumptions!B219 -> 1200 | C12: $/placement | D12: Per successful hire
A13: Add-on Attach Rate | B13: 0.6 | C13: % | D13: 25% of carriers buy add-ons after M3
A14: Avg Add-on Revenue per Carrier | B14: 400 | C14: $/month | D14: Blended avg of add-on products
A15: Overage Revenue per Carrier | B15: 70 | C15: $/month | D15: Avg overage (extra matches)
A16: Overage Adoption Rate | B16: =Assumptions!B169 -> 0.2 | C16: % | D16: 20% of carriers use overages
A18: COGS ASSUMPTIONS
A19: Input | B19: Value | C19: Unit | D19: Notes
A20: Matching Engine COGS | B20: 15 | C20: $/month/carrier | D20: LLM API, compute
A21: Placement COGS | B21: 65 | C21: $/placement | D21: Driver CAC + processing
A22: Add-on COGS % | B22: 0.1 | C22: % | D22: 10% of add-on revenue
A25: PROFIT & LOSS - 24 MONTH PROJECTION
C26: YEAR 1 | O26: YEAR 2
A27: Category | B27: Line Item | C27: M1 | D27: M2 | E27: M3 | F27: M4 | G27: M5 | H27: M6 | I27: M7 | J27: M8 | K27: M9 | L27: M10 | M27: M11 | N27: M12 | O27: M13 | P27: M14 | Q27: M15 | R27: M16 | S27: M17 | T27: M18 | U27: M19 | V27: M20 | W27: M21 | X27: M22 | Y27: M23 | Z27: M24 | AA27: Y1 Total | AB27: Y2 Total
A28: Metrics | B28: Active Carriers | C28: ='Churn Model'!E29 -> 4 | D28: ='Churn Model'!E30 -> 5 | E28: ='Churn Model'!E31 -> 6 | F28: ='Churn Model'!E32 -> 7 | G28: ='Churn Model'!E33 -> 8 | H28: ='Churn Model'!E34 -> 9 | I28: ='Churn Model'!E35 -> 10 | J28: ='Churn Model'!E36 -> 11 | K28: ='Churn Model'!E37 -> 12 | L28: ='Churn Model'!E38 -> 13 | M28: ='Churn Model'!E39 -> 14 | N28: ='Churn Model'!E40 -> 15 | O28: ='Churn Model'!E41 -> 19 | P28: ='Churn Model'!E42 -> 24 | Q28: ='Churn Model'!E43 -> 30 | R28: ='Churn Model'!E44 -> 38 | S28: ='Churn Model'!E45 -> 47 | T28: ='Churn Model'!E46 -> 59 | U28: ='Churn Model'!E47 -> 75 | V28: ='Churn Model'!E48 -> 95 | W28: ='Churn Model'!E49 -> 120 | X28: ='Churn Model'!E50 -> 151 | Y28: ='Churn Model'!E51 -> 190 | Z28: ='Churn Model'!E52 -> 239 | AA28: ='Churn Model'!E40 -> 15 | AB28: ='Churn Model'!E52 -> 239
A29: Revenue | B29: Matching Engine | C29: =C28*$B$11 -> 1196 | D29: =D28*$B$11 -> 1495 | E29: =E28*$B$11 -> 1794 | F29: =F28*$B$11 -> 2093 | G29: =G28*$B$11 -> 2392 | H29: =H28*$B$11 -> 2691 | I29: =I28*$B$11 -> 2990 | J29: =J28*$B$11 -> 3289 | ... Z29: =Z28*$B$11 -> 71461 | AA29: =SUM(C29:N29) -> 34086 | AB29: =SUM(O29:Z29) -> 325013
A30: Revenue | B30: Placement Services | C30: =C28*$B$10*$B$12 -> 24000 | D30: =D28*$B$10*$B$12 -> 30000 | E30: =E28*$B$10*$B$12 -> 36000 | F30: =F28*$B$10*$B$12 -> 42000 | G30: =G28*$B$10*$B$12 -> 48000 | H30: =H28*$B$10*$B$12 -> 54000 | I30: =I28*$B$10*$B$12 -> 60000 | J30: =J28*$B$10*$B$12 -> 66000 | ... Z30: =Z28*$B$10*$B$12 -> 1434000 | AA30: =SUM(C30:N30) -> 684000 | AB30: =SUM(O30:Z30) -> 6522000
A31: Revenue | B31: Add-on Products | C31: 0 | D31: 0 | E31: 0 | F31: =F28*$B$13*$B$14 -> 1680 | G31: =G28*$B$13*$B$14 -> 1920 | H31: =H28*$B$13*$B$14 -> 2160 | I31: =I28*$B$13*$B$14 -> 2400 | J31: =J28*$B$13*$B$14 -> 2640 | K31: =K28*$B$13*$B$14 -> 2880 | L31: =L28*$B$13*$B$14 -> 3120 | M31: =M28*$B$13*$B$14 -> 3360 | ... Z31: =Z28*$B$13*$B$14 -> 57360 | AA31: =SUM(C31:N31) -> 23760 | AB31: =SUM(O31:Z31) -> 260880
A32: Revenue | B32: Overage Revenue | C32: =C28*$B$16*$B$15 -> 56 | D32: =D28*$B$16*$B$15 -> 70 | E32: =E28*$B$16*$B$15 -> 84 | F32: =F28*$B$16*$B$15 -> 98 | G32: =G28*$B$16*$B$15 -> 112 | H32: =H28*$B$16*$B$15 -> 126 | I32: =I28*$B$16*$B$15 -> 140 | J32: =J28*$B$16*$B$15 -> 154 | ... Z32: =Z28*$B$16*$B$15 -> 3346 | AA32: =SUM(C32:N32) -> 1596 | AB32: =SUM(O32:Z32) -> 15218
A33: Revenue | B33: TOTAL REVENUE | C33: =SUM(C29:C32) -> 25252 | D33: =SUM(D29:D32) -> 31565 | E33: =SUM(E29:E32) -> 37878 | F33: =SUM(F29:F32) -> 45871 | G33: =SUM(G29:G32) -> 52424 | H33: =SUM(H29:H32) -> 58977 | I33: =SUM(I29:I32) -> 65530 | J33: =SUM(J29:J32) -> 72083 | ... Z33: =SUM(Z29:Z32) -> 1566167 | AA33: =SUM(C33:N33) -> 743442 | AB33: =SUM(O33:Z33) -> 7123111
A34: COGS | B34: Matching Engine COGS | C34: =C28*$B$20 -> 60 | D34: =D28*$B$20 -> 75 | E34: =E28*$B$20 -> 90 | F34: =F28*$B$20 -> 105 | G34: =G28*$B$20 -> 120 | H34: =H28*$B$20 -> 135 | I34: =I28*$B$20 -> 150 | J34: =J28*$B$20 -> 165 | ... Z34: =Z28*$B$20 -> 3585 | AA34: =SUM(C34:N34) -> 1710 | AB34: =SUM(O34:Z34) -> 16305
A35: COGS | B35: Placement COGS | C35: =C28*$B$10*$B$21 -> 1300 | D35: =D28*$B$10*$B$21 -> 1625 | E35: =E28*$B$10*$B$21 -> 1950 | F35: =F28*$B$10*$B$21 -> 2275 | G35: =G28*$B$10*$B$21 -> 2600 | H35: =H28*$B$10*$B$21 -> 2925 | I35: =I28*$B$10*$B$21 -> 3250 | J35: =J28*$B$10*$B$21 -> 3575 | ... Z35: =Z28*$B$10*$B$21 -> 77675 | AA35: =SUM(C35:N35) -> 37050 | AB35: =SUM(O35:Z35) -> 353275
